Workbook
Name 攻撃スタイル: リスト!$C$3:$C$5
Name 身体タイプ: リスト!$F$3:$F$5
Name 能力タイプ: リスト!$A$3:$A$8
Name 能力分類: リスト!$A$3:$A$8

Sheet リスト
A1: 能力タイプ | C1: 活性タイプ | D1: 活性タイプ | F1: 身体タイプ | H1: 在住エリア | K1: ＳＰＥ | M1: 所属 | P1: 判定ダイス | R1: 幸運ボーナス | T1: 容姿 | V1: 発動系統 | X1: 付加効果 | Z1: ＳＥ | AH1: 特殊武装 | AN1: ライフ＆ライフ | AP1: スタンス＆トゥルー | AR1: カルマ | AU1: 崩壊症状 | AW1: カルマ | AY1: 消費アイテム | BC1: フレーバー
A2: － | C2: － | D2: － | F2: － | H2: － | K2: － | M2: － | P2: １Ｄ６ | R2: -2 | T2: － | V2: － | X2: － | Z2: － | AB2: － | AD2: 0 | AF2: － | AH2: － | AN2: － | AP2: － | AR2: － | AU2: － | AW2: － | AY2: － | BC2: －
A3: ノーマル | C3: 覚醒型 | D3: 増強型 | F3: ナチュラル | H3: 上層【アースガルズ】 | K3: 奇跡 | M3: 司法機関グングニル | P3: ２Ｄ６ | R3: -1 | T3: Ｓ | V3: 攻撃発動 | X3: 強化【行】 | Z3: トラップ | AB3: 攻撃型 | AD3: 1 | AF3: 力技 | AH3: アタッチメント【スペック－０】 | AN3: 異形 | AP3: 正義 | AR3: 昇華者【リバーサー】 | AU3: 聴覚崩壊 | AW3: 昇華者 【リバーサー】 | AY3: マグタフ 【因子１】 | BC3: 行為発動
A4: サイキッカー | C4: 増強型 | D4: 反応型 | F4: コーディネーター | H4: 中層【ミズガルズ】 | K4: 悪運 | M4: 民主機構オルレアン | P4: ３Ｄ６ | R4: 0 | T4: Ａ | V4: 精神発動 | X4: 強化【攻】 | Z4: チャージ | AB4: 速度型 | AD4: 2 | AH4: ロケットランチャー【スペック－４】 | AN4: 暴走 | AP4: 中庸 | AR4: 駆け出し【ルーキー】 | AU4: 視覚崩壊 | AW4: 駆け出し 【ルーキー】 | AY4: マグタフＥＸ 【因子１】 | BC4: チェイン発動
A5: エスパー | C5: 反応型 | D5: 感覚型 | F5: サイボーグ | H5: 下層【ヘルヘイム】 | K5: 闘志 | M5: 抑制機構テセウス | R5: 1 | T5: Ｂ | V5: 防御発動 | X5: 強化【防】 | Z5: ドレイン | AB5: 探索型 | AD5: 3 | AF5: － | AH5: パイルバンカー【スペック－３】 | AN5: 崩壊 | AP5: 悪徳 | AR5: 新鋭【ニューフェイス】 | AU5: 言語崩壊 | AW5: 新鋭 【ニューフェイス】 | AY5: マグタフＺ 【因子２】 | BC5: 【ＳＰＥ】 奇跡
A6: トランサー | C6: 感覚型 | D6: 回復型 | F6: ハイブリッド | H6: 不明 | K6: リベンジ | M6: ルーン企業連 | R6: 2 | T6: Ｃ | V6: 付加発動 | X6: 強化【抵】 | Z6: ブレイク | AD6: 4 | AF6: 威圧 | AH6: 荷電粒子砲【スペック－３】 | AN6: 恩恵 | AP6: 優柔不断 | AR6: 初心【ビギナーズラック】 | AU6: 身体崩壊 | AW6: 初心 【ビギナーズラック】 | AY6: トランス 【因子１】 | BC6: 【ＳＰＥ】 悪運
A7: クリエイター | C7: 回復型 | F7: アンドロイド | K7: リテイク | M7: チーム世紀末覇者 | R7: 3 | T7: Ｄ | V7: 行為発動 | X7: 強化【命】 | Z7: ペネトレイション | AD7: 5 | AH7: 手榴弾【スペック－３】 | AN7: 実験 | AP7: 唯我独尊 | AR7: 失敗談【ミステイク】 | AU7: 精神崩壊 | AW7: 失敗談 【ミステイク】 | AY7: ライズ 【因子２】 | BC7: 【ＳＰＥ】 闘志
A8: アンノウン | F8: ロボット | K8: 逆転 | M8: スヴァルトアルフ | T8: Ｅ | V8: ＡＥ【重撃】 | X8: 強化【回】 | Z8: オールレンジ | AD8: 6 | AF8: － | AH8: トラップボム【スペック－３】 | AN8: 才能 | AP8: 天真爛漫 | AR8: 伏兵【ダークホース】 | AU8: 記憶崩壊 | AW8: 伏兵 【ダークホース】 | AY8: ネクスト 【因子３】 | BC8: 【ＳＰＥ】 リベンジ
K9: 絆 | M9: フリーランス | X9: 強化【技】 | Z9: コンティニュー | AD9: 7 | AF9: 観察眼 | AH9: レールガン【スペック－３】 | AN9: 喪失 | AP9: 家族 | AR9: 調律者【バランサー】 | AW9: 調律者 【バランサー】 | AY9: ユートピア 【因子１】 | BC9: 【ＳＰＥ】 リテイク
K10: 激励 | Q10: 特殊技 | X10: 強化【解】 | Z10: テリトリー | AD10: 8 | AH10: ドリル【スペック－３】 | AN10: 復讐 | AP10: 友情 | AR10: 崩壊者【ディケイド】 | AW10: 崩壊者 【ディケイド】 | AY10: パンドラ 【因子１】 | BC10: 【ＳＰＥ】 逆転
F11: 活性 | K11: 不屈 | Q11: － | X11: 減衰【行】 | Z11: リスク | AD11: 9 | AF11: － | AH11: ブラスター【スペック－２】 | AN11: 逃亡 | AP11: 愛 | AR11: 喪失者【ミッシング】 | AW11: 喪失者 【ミッシング】 | AY11: マグタフ黒 【因子４】 | BC11: 【ＳＰＥ】 絆
A12: 暴走症状 | C12: 次回追加 | F12: － | K12: 瞑想 | Q12: 行為発動 | X12: 減衰【攻】 | Z12: オート | AD12: 10 | AF12: 察知 | AH12: 高周波ブレード【スペック－２】 | AN12: 傷病 | AP12: 仁義 | AR12: 突然変異【アナザー】 | AW12: 突然変異 【アナザー】 | AY12: 使い捨てランチャー 【因子１０】 | BC12: 【ＳＰＥ】 激励
A13: － | C13: － | F13: ＋１ | K13: 鎮静 | Q13: チェイン発動 | X13: 減衰【防】 | Z13: セミオート | AD13: 11 | AH13: 火炎放射器【スペック－２】 | AN13: 贖罪 | AP13: 礼節 | AR13: 覚醒者【アクトレイザー】 | AW13: 覚醒者 【アクトレイザー】 | AY13: 違法グレネード 【因子４】 | BC13: 【ＳＰＥ】 不屈
A14: 制御異常 | C14: 生還者（補正なし） | F14: ＋２ | K14: 精神凌駕 | Q14: 特殊技 | X14: 減衰【抵】 | Z14: リフレクション | AD14: 12 | AF14: － | AH14: 電子ドラッグ【スペック－２】 | AN14: 裏切り | AP14: 誇り | AR14: 探索者【シャープネス】 | AW14: 探索者 【シャープネス】 | AY14: ＥＣＭ【Ｐ】 【因子４】 | BC14: 【ＳＰＥ】 瞑想
A15: 過負荷 | C15: 初期暴走率＋５％ | F15: ＋３ | K15: 愛 | Q15: 特殊武装 | V15: ＡＥ | X15: 減衰【命】 | Z15: パーフェクト | AF15: 知識 | AH15: スタンガン【スペック－１】 | AN15: 名声 | AP15: 男性的 | AR15: 修羅【アタッカー】 | AW15: 修羅 【アタッカー】 | AY15: ＥＣＭ【Ｅ】 【因子４】 | BC15: 【ＳＰＥ】 鎮静
A16: 聴覚異常 | C16: 初期暴走率＋１０％ | K16: 瞬動 | M16: ＮＰＣ Lv.1 上限10pt | V16: － | X16: 減衰【回】 | AH16: ワイヤートラップ【スペック－１】 | AN16: 悪名 | AP16: 中性的 | AR16: 寵愛【アイドル】 | AW16: 寵愛 【アイドル】 | AY16: ＥＣＭ【Ｔ】 【因子４】 | BC16: 【ＳＰＥ】 精神凌駕
A17: 視覚異常 | C17: 初期暴走率＋１５％ | K17: 限界突破 | M17: ＮＰＣ Lv.2 上限15pt | V17: コンセ | X17: 減衰【技】 | AF17: － | AH17: フラッシュガン【スペック－２】 | AN17: 孤独 | AP17: 女性的 | AR17: 英雄【ブレイブ】 | AW17: 英雄 【ブレイブ】 | AY17: ＥＣＭ【Ｃ】 【因子４】 | BC17: 【ＳＰＥ】 愛
A18: 身体異常 | C18: 初期暴走率＋２０％ | K18: 防衛本能 | M18: ＮＰＣ Lv.3 上限20pt | V18: ブースト | X18: 減衰【解】 | AF18: 技術 | AH18: 増強アンプル【スペック－1】 | AN18: 義理の家族 | AP18: 一途 | AR18: 凡骨【ナチュラルボーン】 | AW18: 凡骨 【ナチュラルボーン】 | AY18: パイル予備弾 【因子２】 | BC18: 【ＳＰＥ】 瞬動
A19: 能力異常 | C19: 暴走崩壊者 | K19: 共鳴 | M19: ＮＰＣ Lv.4 上限25pt | V19: エール | X19: 回復 | AH19: 強化シナプス【スペック－1】 | AN19: 機械化 | AP19: 好色 | AR19: 殺し屋【ザ・キラー】 | AW19: 殺し屋 【ザ・キラー】 | AY19: 荷電粒子予備弾 【因子２】 | BC19: 【ＳＰＥ】 限界突破
A20: 言語異常 | K20: パージ | M20: ＮＰＣ Lv.5 上限30pt | V20: 死力 | X20: 拡張 | AF20: － | AH20: スモーク【スペック－1】 | AN20: 被害者 | AP20: 同性愛 | AR20: 武器屋【マスター】 | AW20: 武器屋 【マスター】 | AY20: スタン予備弾 【因子２】 | BC20: 【ＳＰＥ】 防衛本能
A21: 記憶異常 | C21: 持ち越し抑制ダイス | K21: 奥義 | M21: ＮＰＣ Lv.MAX ALL12 | V21: 怪力乱神 | X21: 制限 | AF21: 隠密 | AH21: サイキックジャミング【スペック－1】 | AN21: 成功 | AP21: 倹約 | AR21: 守護者【イージス】 | AW21: 守護者 【イージス】 | AY21: フラッシュ予備弾 【因子２】 | BC21: 【ＳＰＥ】 共鳴
A22: 精神異常 | C22: － | K22: 大器 | V22: 臥薪嘗胆 | X22: 幸運 | AH22: 神経ジャマー【スペック－1】 | AN22: 没落 | AP22: 几帳面 | AR22: 反撃者【リベリオン】 | AW22: 反撃者 【リベリオン】 | AY22: バーサーカー 【因子１】 | BC22: 【ＳＰＥ】 パージ
A23: 忘我 | C23: 1 | K23: 熟練 | V23: 才気煥発 | X23: 追加【命】 | AF23: － | AH23: トランスキャンセラー【スペック－1】 | AN23: 権力 | AP23: 独立 | AR23: 影の者【アサシン】 | AW23: 影の者 【アサシン】 | AY23: ハイウェイ 【因子１】 | BC23: 【ＳＰＥ】 奥義
C24: 2 | K24: エキスパート | V24: 明鏡止水 | X24: 追加【回】 | AF24: 俊敏 | AH24: クリエイトノイザー【スペック－1】 | AN24: 勤労 | AP24: 物欲 | AR24: 癒し手【ヒーラー】 | AW24: 癒し手 【ヒーラー】 | AY24: 煙幕 【因子１】 | BC24: 【ＳＰＥ】 大器
C25: 3 | T25: 技系統 | V25: 画竜点睛 | X25: 追加【技】 | AH25: アーマー【スペック－1】 | AN25: 無名 | AP25: リーダーシップ | AR25: 使役者【ブリーダー】 | AW25: 使役者 【ブリーダー】 | BC25: 【ＳＰＥ】 熟練
C26: 4 | T26: － | V26: 電光石火 | X26: 追加【解】 | AF26: － | AH26: ブラックボックス【スペック－1】 | AN26: 裏社会 | AP26: 慎重 | AR26: 不幸【アンラッキー】 | AW26: 不幸 【アンラッキー】 | BC26: 【ＳＰＥ】 エキスパート
C27: 5 | T27: 攻撃 | V27: 運否天賦 | X27: 混乱 | AF27: 話術 | AH27: パワードスーツ【スペック－1】 | AN27: 平凡 | AP27: 豪胆 | AR27: 抗体【アンチボディ】 | AW27: 抗体 【アンチボディ】 | BC27: 【カルマ】 昇華者
T28: 回復 | V28: 待機 | X28: 複製 | AH28: スキャンスコープ【スペック－1】 | AN28: 商人 | AP28: ポジティブ | AR28: 愚者【トラブルメイカー】 | AW28: 愚者 【トラブルメイカー】 | BC28: 【カルマ】 駆け出し
T29: 防御 | V29: 移動 | X29: 制止 | AF29: － | AH29: 高感度センサー【スペック－1】 | AN29: 犯罪 | AP29: 自由 | AR29: 不死身【アンデット】 | AW29: 不死身 【アンデット】 | BC29: 【カルマ】 新鋭
T30: 補正 | V30: 移動攻撃 | X30: 継続 | AF30: 読心 | AH30: 高演算電脳【スペック－1】 | AN30: 技術者 | AP30: お人好し | AR30: 奉仕者【トレーダー】 | AW30: 奉仕者 【トレーダー】 | BC30: 【カルマ】 初心
T31: 状態異常 | V31: 離脱 | X31: 操作 | AH31: 高性能マニピュレーター【スペック－1】 | AN31: 宗教 | AP31: 目立ちたがり | AR31: 闇商人【ディーラー】 | AW31: 闇商人 【ディーラー】 | BC31: 【カルマ】 失敗談
T32: 創造 | V32: 参戦 | X32: 創造 | AF32: － | AH32: 光学迷彩【スペック－1】 | AN32: 芸術 | AP32: 友好 | AR32: 破壊者【デストロイヤー】 | AW32: 破壊者 【デストロイヤー】 | BC32: 【カルマ】 伏兵
T33: その他 | V33: 参戦攻撃 | X33: 性質【威力】 | AF33: 閃き | AH33: 高出力ブースター【スペック－1】 | AN33: 忠誠 | AP33: 臆病 | AR33: 職人【プロフェッショナル】 | AW33: 職人 【プロフェッショナル】 | BC33: 【カルマ】 調律者
V34: 回避放棄 | X34: 性質【反応】 | AH34: 心拍スカウター【スペック－1】 | AN34: 野心 | AP34: ネガティブ | AR34: 鷹の目【ホークアイ】 | AW34: 鷹の目 【ホークアイ】 | BC34: 【カルマ】 崩壊者
V35: カバーリング | X35: 性質【耐性】 | AF35: － | AH35: 高出力ブースター【スペック－1】 | AN35: 秘密 | AP35: 寂しがり屋 | AR35: 幻影【ファントム】 | AW35: 幻影 【ファントム】 | BC35: 【カルマ】 喪失者
V36: カバー態勢 | X36: 性質【感覚】 | AF36: 幸運 | AH36: 心拍スカウター【スペック－1】 | AN36: 探求 | AP36: 嫉妬 | AR36: 無血開城【ピースメイカー】 | AW36: 無血開城 【ピースメイカー】 | BC36: 【カルマ】 突然変異
V37: 手加減 | X37: 性質【幸運】 | AN37: 武道 | AP37: 疑心 | AR37: 人外【レジェンド】 | AW37: 人外 【レジェンド】 | BC37: 【カルマ】 覚醒者
V38: カウンター | X38: 限定耐性 | AN38: 研究 | AP38: 虚偽 | AR38: 希少種【レア】 | AW38: 希少種 【レア】 | BC38: 【カルマ】 探索者
V39: 不意打ち | X39: 限定無効 | AP39: 温厚 | AR39: 勇猛【ベルセルク】 | AW39: 勇猛 【ベルセルク】 | BC39: 【カルマ】 修羅
V40: ノックアウト | X40: 限定吸収 | AP40: 慈愛 | AR40: 魔性【フェロモン】 | AW40: 魔性 【フェロモン】 | BC40: 【カルマ】 寵愛
...

Sheet キャラシート
B2: キャラクター名 | J2: ＰＬ名 | N2: 次回セッション | T2: ※先にこちらの欄を入力する事で左欄にある程度数値が自動反映されます
B3: 園 松温（その しょうおん） | J3: はむぱん | N3: 次回状態 | P3: 生還者（補正なし） | AC3: 基礎技能値 | AF3: 運ボーナス | AG3: 基礎技能値 | AJ3: 運ボーナス
N4: 持ち越し因子ダイス | P4: 4 | U4: →手入力 | W4: →選択入力 | Y4: →自動反映 | AA4: →反映結果 | AC4: 力技 | AE4: =(AA10*2) -> 4 | AF4: =IF(AA16<18,IF(AA16<14,IF(AA16<10,IF(AA16<5,IF(AA16<3,"-2","-1"),0),"+1"),"+2"),"+3") -> -2 | AG4: 隠密 | AI4: =AA14+AA15 -> 16 | AJ4: =IF(AA16<18,IF(AA16<14,IF(AA16<10,IF(AA16<5,IF(AA16<3,"-2","-1"),0),"+1"),"+2"),"+3") -> -2
B5: 性別 | D5: 年齢 | F5: 身長 | H5: 容姿 | J5: カルマ | N5: 崩壊深度 | P5: － | AC5: 威圧 | AE5: =AA10+AA11 -> 6 | AF5: =IF(AA16<18,IF(AA16<14,IF(AA16<10,IF(AA16<5,IF(AA16<3,"-2","-1"),0),"+1"),"+2"),"+3") -> -2 | AG5: 俊敏 | AI5: =(AA15*2) -> 16 | AJ5: =IF(AA16<18,IF(AA16<14,IF(AA16<10,IF(AA16<5,IF(AA16<3,"-2","-1"),0),"+1"),"+2"),"+3") -> -2
B6: 男 | D6: 12 | F6: 163 | H6: Ａ | J6: 芸人【エンターテイナー】 | N6: 後遺症 | P6: － | T6: ▼ステータス計算 | AC6: 観察眼 | AE6: =ROUNDDOWN((AA55/2),0)+AA12 -> 9 | AF6: =IF(AA16<18,IF(AA16<14,IF(AA16<10,IF(AA16<5,IF(AA16<3,"-2","-1"),0),"+1"),"+2"),"+3") -> -2 | AG6: 話術 | AI6: =AA14+AA12 -> 14 | AJ6: =IF(AA16<18,IF(AA16<14,IF(AA16<10,IF(AA16<5,IF(AA16<3,"-2","-1"),0),"+1"),"+2"),"+3") -> -2
B7: 職業 | D7: スネ夫 | J7: 所属 | K7: フリーランス | N7: － | P7: － | T7: 能力タイプ | V7: =C10 -> ノーマル | X7: 身体タイプ | Z7: =F10 -> ナチュラル | AC7: 察知 | AE7: =ROUNDDOWN((AA55/2),0)+AA15 -> 11 | AF7: =IF(AA16<18,IF(AA16<14,IF(AA16<10,IF(AA16<5,IF(AA16<3,"-2","-1"),0),"+1"),"+2"),"+3") -> -2 | AG7: 読心 | AI7: =ROUNDDOWN((AA55/2),0)+AA13 -> 7 | AJ7: =IF(AA16<18,IF(AA16<14,IF(AA16<10,IF(AA16<5,IF(AA16<3,"-2","-1"),0),"+1"),"+2"),"+3") -> -2
J8: 在住エリア | K8: 上層【アースガルズ】 | N8: － | P8: － | T8: 基礎パラメーター | AA8: 総パラ | AC8: 知識 | AE8: =(AA12*2) -> 12 | AF8: =IF(AA16<18,IF(AA16<14,IF(AA16<10,IF(AA16<5,IF(AA16<3,"-2","-1"),0),"+1"),"+2"),"+3") -> -2 | AG8: 閃き | AI8: =ROUNDDOWN((AA55/2),0)+AA16 -> 5 | AJ8: =IF(AA16<18,IF(AA16<14,IF(AA16<10,IF(AA16<5,IF(AA16<3,"-2","-1"),0),"+1"),"+2"),"+3") -> -2
U9: 基礎pt | V9: フリーpt | W9: 計① | X9: 能力者付与pt | Y9: ノーマル付与pt | Z9: 身体付与pt | AA9: ①＋② | AC9: 技術 | AE9: =AA14+AA13 -> 12 | AF9: =IF(AA16<18,IF(AA16<14,IF(AA16<10,IF(AA16<5,IF(AA16<3,"-2","-1"),0),"+1"),"+2"),"+3") -> -2 | AG9: 幸運 | AI9: =(AA16*2) -> 4 | AJ9: =IF(AA16<18,IF(AA16<14,IF(AA16<10,IF(AA16<5,IF(AA16<3,"-2","-1"),0),"+1"),"+2"),"+3") -> -2
B10: 能力タイプ | C10: ノーマル | E10: 身体タイプ | F10: ナチュラル | J10: ライフパス | T10: 筋力 | U10: 2 | V10: -1 | W10: =SUM(U10:V10) -> 1 | X10: =IF(C10="トランサー",2,0) -> 0 | Y10: 1 | Z10: =IF(F10="サイボーグ",1,0) -> 0 | AA10: =W10+AA24+SUM(X10:Z10)-T70 -> 2
J11: ライフ＆ライフ | L11: 権力 | N11: スタンス | P11: 唯我独尊 | T11: 耐久 | U11: 2 | V11: 1 | W11: =SUM(U11:V11) -> 3 | X11: =IF(C10="サイキッカー",1,0) -> 0 | Y11: 1 | Z11: =IF(F10="ロボット",1,0) -> 0 | AA11: =W11+AA25+SUM(X11:Z11)-U70 -> 4
L12: 才能 | N12: トゥルー | P12: 寂しがり屋 | T12: 知力 | U12: 2 | V12: 2 | W12: =SUM(U12:V12) -> 4 | X12: =IF(C10="エスパー",1,0)+IF(C10="アンノウン",1,0) -> 0 | Y12: 1 | Z12: =IF(F10="コーディネーター",1,0) -> 0 | AA12: =W12+AA26+SUM(X12:Z12)-V70 -> 6 | AC12: パラメーター基準値
B13: ＳＰＥ | C13: 奇跡 | E13: 活性タイプ | F13: 感覚型 | J13: キャライメージ | T13: 精神 | U13: 2 | W13: =SUM(U13:V13) -> 2 | X13: =IF(C10="エスパー",2,0)+IF(C10="クリエイター",1,0) -> 0 | Z13: =IF(F10="ナチュラル",1,0) -> 1 | AA13: =W13+AA27+SUM(X13:Z13)-W70 -> 4 | AC13: 無能 | AD13: 貧弱 | AE13: 常人 | AG13: 秀才 | AI13: 達人 | AJ13: 天才
O14: 探索技能 | Q14: ＳＰＥ補正 | T14: 器用 | U14: 2 | V14: 5 | W14: =SUM(U14:V14) -> 7 | X14: =IF(C10="クリエイター",2,0) -> 0 | Z14: =IF(F10="ハイブリッド",1,0) -> 0 | AA14: =W14+AA28+SUM(X14:Z14)-X70 -> 8 | AC14: 1～２ | AD14: ３～４ | AE14: ５～９ | AG14: １０～１３ | AI14: １４～１７ | AJ14: １８～
O15: 力技 | P15: =ROUNDDOWN((AE4+AF4)/2,0) -> 1 | T15: 敏捷 | U15: 2 | V15: 4 | W15: =SUM(U15:V15) -> 6 | X15: =IF(C10="サイキッカー",2,0)+IF(C10="トランサー",1,0) -> 0 | Z15: =IF(F10="アンドロイド",1,0) -> 0 | AA15: =W15+AA29+SUM(X15:Z15)-Y70 -> 8
B16: ステータス | F16: パラメーター | O16: 威圧 | P16: =ROUNDDOWN((AE5+AF5)/2,0) -> 2 | T16: 運 | U16: 2 | V16: -1 | W16: =SUM(U16:V16) -> 1 | X16: =IF(C10="アンノウン",2,0) -> 0 | Z16: 0 | AA16: =W16+AA30+SUM(X16:Z16)-Z70 -> 2
B17: HP | D17: =ABS(AA49) -> 8 | F17: 筋力 | H17: =AA10 -> 2 | O17: 観察眼 | P17: =ROUNDDOWN((AE6+AF6)/2,0) -> 3 | T17: 計 | U17: =SUM(U10:U16) -> 14 | V17: =SUM(V10:V16) -> 10 | W17: =SUM(W10:W16) -> 24 | X17: =SUM(X10:X16) -> 0 | Y17: =SUM(Y10:Y16) -> 3 | Z17: =SUM(Z10:Z16) -> 1 | AA17: =SUM(AA10:AA16) -> 34 | AC17: 運ボーナス
F18: 耐久 | H18: =AA11 -> 4 | O18: 察知 | P18: =ROUNDDOWN((AE7+AF7)/2,0) -> 4 | U18: =28-U17 -> 14 | V18: =10-V17 -> 0 | X18: =3-X17 -> 3 | Y18: =3-Y17 -> 0 | Z18: =1-Z17 -> 0 | AC18: 運１～２ | AE18: ― | AH18: 基礎技能値－２
B19: PP | D19: =ABS(AA50) -> 17 | F19: 知力 | H19: =AA12 -> 6 | O19: 知識 | P19: =ROUNDDOWN((AE8+AF8)/2,0) -> 5 | U19: ↑フリーpt入力計↑ 計①がゼロ以下はＮＧ | X19: ↑身体・能力タイプｐｔ↑ ノーマルは手入力 | AC19: 運３～４ | AE19: ― | AH19: 基礎技能値－１
F20: 精神 | H20: =AA13 -> 4 | O20: 技術 | P20: =ROUNDDOWN((AE9+AF9)/2,0) -> 5 | AC20: 運５～９ | AE20: ― | AH20: ―
B21: 暴走率 | D21: =AA51 -> 15 | F21: 器用 | H21: =AA14 -> 8 | O21: 隠密 | P21: =ROUNDDOWN((AI4+AJ4)/2,0) -> 7 | AC21: 運１０～１３ | AE21: ― | AH21: 基礎技能値+１
F22: 敏捷 | H22: =AA15 -> 8 | O22: 俊敏 | P22: =ROUNDDOWN((AI5+AJ5)/2,0) -> 7 | T22: キャラ特性付与パラメーター | Z22: キャラpt | AA22: =5+IF(C10="ノーマル",1,0) -> 6 | AC22: 運１４～１７ | AE22: 命中・回避判定ダイス＋１Ｄ６ | AH22: 基礎技能値+２
B23: 防御力 | D23: =AA52 -> 2 | F23: 運 | H23: =AA16 -> 2 | O23: 話術 | P23: =ROUNDDOWN((AI6+AJ6)/2,0) -> 6 | T23: キャラ特性 | U23: 逃げ足 | V23: 親の七光り | W23: 自尊心 | X23: 立ち回りの上手さ | Y23: 電脳ゲーム好き | AA23: 計② | AC23: 運１８～２０ | AE23: 命中・回避判定ダイス＋１Ｄ６ | AH23: 基礎技能値+３
O24: 読心 | P24: =ROUNDDOWN((AI7+AJ7)/2,0) -> 2 | T24: =T10 -> 筋力 | AA24: =SUM(U24:Z24) -> 0
B25: 精神抵抗 | D25: =AA53 -> 2 | F25: 能力精度 | H25: =AA58 -> 6 | O25: 閃き | P25: =ROUNDDOWN((AI8+AJ8)/2,0) -> 1 | T25: =T11 -> 耐久 | AA25: =SUM(U25:Z25) -> 0
O26: 幸運 | P26: =ROUNDDOWN((AI9+AJ9)/2,0) -> 1 | T26: =T12 -> 知力 | X26: 1 | AA26: =SUM(U26:Z26) -> 1
B27: 行動値 | D27: =AA54 -> 6 | F27: 発動スペック | H27: =AA59 -> 2 | O27: キャラ特性 | T27: =T13 -> 精神 | W27: 1 | AA27: =SUM(U27:Z27) -> 1 | AC27: ◆ 探索技能補足説明 ◆
O28: =U23 -> 逃げ足 | T28: =T14 -> 器用 | X28: 1 | AA28: =SUM(U28:Z28) -> 1
O29: =V23 -> 親の七光り | T29: =T15 -> 敏捷 | U29: 2 | AA29: =SUM(U29:Z29) -> 2 | AC29: 技能名 | AE29: 説明
B30: 命中・回避 | F30: 攻撃力 | O30: =W23 -> 自尊心 | T30: =T16 -> 運 | V30: 1 | AA30: =SUM(U30:Z30) -> 1 | AC30: 力技 | AE30: 物を動かす、ドアを破るなど、力で物事を突破する際に必要な判定技能。
B31: ＳＳ | C31: =AA55 -> 6 | D31: =IF(AA16<14,1,2) -> 1 | F31: 格闘 | G31: =V38 -> 1 | H31: =W38 -> 0 | O31: =X23 -> 立ち回りの上手さ | T31: 消費pt | U31: =SUM(U24:U30) -> 2 | V31: =SUM(V24:V30) -> 1 | W31: =SUM(W24:W30) -> 1 | X31: =SUM(X24:X30) -> 2 | Y31: =SUM(Y24:Y30) -> 0 | Z31: =SUM(Z24:Z30) -> 0 | AA31: =SUM(U31:Z31) -> 6 | AC31: 観察眼 | AE31: 物事・現場を観察し、何かに気づけるかどうかの判定技能。
O32: =Y23 -> 電脳ゲーム好き | AA32: =AA22-AA31 -> 0 | AC32: 閃き | AE32: 推理・考察時に何かを思い付けるかどうかの判定技能。
B33: 命中力 | C33: =AA56 -> 10 | D33: =IF(AA16<14,1,2) -> 1 | F33: 武器 | G33: =V39 -> 3 | H33: =W39 -> 0 | O33: =Z23 -> 0 | T33: 攻撃力取得 1D6/3点 固定値１/1点 点移行/2点 | AC33: 察知 | AE33: 突然の出来事・気配等に反応できるか・気づけるかどうかの判定技能。
O34: 睡眠回復量 | AC34: 知識 | AE34: 物事・情報・使用方法などについて知っているかどうかの判定技能。
B35: 回避力 | C35: =AA57 -> 11 | D35: =IF(AA16<14,1,2) -> 1 | F35: 能力 | G35: =V40 -> 2 | H35: =W40 -> 0 | O35: ＨＰ＆ＰＰ回復量 | Q35: =ROUNDDOWN((AA11/3),0) -> 1 | T35: 取得結果 | X35: 取得点 | AC35: 技術 | AE35: 機械を修理する、鍵開けを行うなど、技術を要求される場合の判定技能。
O36: 暴走率回復量 | Q36: =ROUNDDOWN((AA13/3),0) -> 1 | X36: 格闘点 | Y36: 武器点 | Z36: 能力点 | AC36: 隠密 | AE36: 身を隠す、対象を追跡する、物を隠す際の判定技能。
V37: 取得ダイス | W37: 取得固定値 | X37: =Z63-SUM(X38:X40) -> 0 | Y37: =Z64-SUM(Y38:Y40) -> 0 | Z37: =Z65-SUM(Z38:Z40) -> 0 | AA37: 移行結果 | AC37: 俊敏 | AE37: 逃げる、対象を追いかける、高所からの着地ができるかなどの判定技能。
B38: アイテム | J38: 能力名 | T38: 格闘攻撃 | V38: 1 | X38: 2 | Z38: 2 | AA38: =ROUNDDOWN((Y38/2),0)+ROUNDDOWN((Z38/2),0)+(X38) -> 3 | AC38: 威圧 | AE38: 強制的に対象を従わせる、威嚇などで黙らせるなどに必要な判定技能。
B39: 特殊武装 | E39: 消費アイテム／アタッチメント | H39: 所持品 | J39: なし | T39: 武器攻撃 | V39: 3 | Y39: 9 | AA39: =ROUNDDOWN((X39/2),0)+ROUNDDOWN((Z39/2),0)+(Y39) -> 9 | AC39: 話術 | AE39: 説得・言いくるめ・交渉など、話術が必要な際の判定技能。
B40: フラッシュガン【スペック－２】 | E40: 煙幕 【因子１】 | H40: 厳かな服 | T40: 能力攻撃 | V40: 2 | Z40: 6 | AA40: =ROUNDDOWN((X40/2),0)+ROUNDDOWN((Y40/2),0)+(Z40) -> 6 | AC40: 読心 | AE40: 対象が嘘をついているかなど、相手の心情を察する判定技能。
B41: － | E41: ユートピア 【因子１】 | H41: 煌びやかな指輪 | V41: ↑数値のみ入力でＯＫ | X41: ▼ ▼ ▼ ▼ | AC41: 幸運 | AE41: 運が試される際の判定技能。
...

Sheet 応用技
B2: 能力応用技 ※応用技は最大８個まで | M2: 行為発動・特殊技 ※フレーバーの行為発動や、技組合せのチェイン発動、 ＡＥ・ＳＰＥを演出の特殊技、特殊武装などをフレーバー技として明記したい場合に入力下さい。
B4: 発動スペック | D4: =キャラシート!H27 -> 2 | E4: 防御発動量 | G4: =ROUNDDOWN((キャラシート!H25)/2,0) -> 3 | H4: 付加補正量 | J4: =ROUNDDOWN((キャラシート!H25)/3,0) -> 2
B8: 技名 | H8: 技系統 | I8: 消費 | J8: 必要スペック | M8: 技名 | R8: 演出 | U8: 消費
M9: ナイフ | R9: 武器攻撃
M12: 効果補足
M13: 父の書斎から盗み出したもの
M17: ※この行には具体的な効果やチェイン発動の組合せをお書き下さい。
B19: 技名 | H19: 技系統 | I19: 消費 | J19: 必要スペック | M19: 技名 | R19: 演出 | U19: 消費
M20: 親の名刺 | R20: 【特殊武装】 アタッチメント | U20: 0.02
M23: 効果補足
M24: わかる人にはわかるかもしれない。
M28: ※この行には具体的な効果やチェイン発動の組合せをお書き下さい。
B30: 技名 | H30: 技系統 | I30: 消費 | J30: 必要スペック | M30: 技名 | R30: 演出 | U30: 消費
R31: －
M34: 効果補足
M39: ※この行には具体的な効果やチェイン発動の組合せをお書き下さい。
B41: 技名 | H41: 技系統 | I41: 消費 | J41: 必要スペック | M41: 技名 | R41: 演出 | U41: 消費
R42: －
M45: 効果補足
M50: ※この行には具体的な効果やチェイン発動の組合せをお書き下さい。
B52: 技名 | H52: 技系統 | I52: 消費 | J52: 必要スペック | M52: 技名 | R52: 演出 | U52: 消費
H53: － | R53: －
B55: 発動系統 | E55: 付加効果 | H55: ＳＥ
B56: － | C56: － | D56: － | E56: － | F56: － | G56: － | H56: － | I56: － | J56: － | M56: 効果補足
E57: － | F57: － | G57: － | H57: － | I57: － | J57: －
B58: 効果補足
B61: ※この行には具体的な補正量やトリガー条件などをお書き下さい。 | M61: ※この行には具体的な効果やチェイン発動の組合せをお書き下さい。
B63: 技名 | H63: 技系統 | I63: 消費 | J63: 必要スペック | M63: 技名 | R63: 演出 | U63: 消費
H64: － | R64: －
B66: 発動系統 | E66: 付加効果 | H66: ＳＥ
B67: － | C67: － | D67: － | E67: － | F67: － | G67: － | H67: － | I67: － | J67: － | M67: 効果補足
E68: － | F68: － | G68: － | H68: － | I68: － | J68: －
B69: 効果補足
B72: ※この行には具体的な補正量やトリガー条件などをお書き下さい。 | M72: ※この行には具体的な効果やチェイン発動の組合せをお書き下さい。
B74: 技名 | H74: 技系統 | I74: 消費 | J74: 必要スペック | M74: 技名 | R74: 演出 | U74: 消費
H75: － | R75: －
B77: 発動系統 | E77: 付加効果 | H77: ＳＥ
B78: － | C78: － | D78: － | E78: － | F78: － | G78: － | H78: － | I78: － | J78: － | M78: 効果補足
E79: － | F79: － | G79: － | H79: － | I79: － | J79: －
B80: 効果補足
...

Sheet クリーチャー
B2: クリーチャー名 | I2: 創造タイプ | K2: － | P2: 能力応用技 ※応用技は最大８個まで
P4: 発動スペック | R4: =F23 -> 2 | S4: 防御発動量 | U4: =ROUNDDOWN((C23)/2,0) -> 3 | V4: 付加補正量 | X4: =ROUNDDOWN((C23)/3,0) -> 2
B5: 使用PP | D5: 0 | F5: クリーチャー判定値 | H5: =C23 -> 6 | I5: =IF(L2="探索型",ROUNDDOWN(D23/3,0)+D23,D23) -> 0 | J5: クリーチャー能力タイプ | L5: －
B8: ステータス | F8: 取得探索技能 | I8: クリーチャーイメージ | P8: 技名 | V8: 技系統 | W8: 消費 | X8: 必要スペック
D9: 変動値 | V9: －
B10: HP | C10: =D5 -> 0 | F10: 取得可能数 | G10: =F23 -> 2
B11: SS | C11: =D5 -> 0 | P11: 発動系統 | S11: 付加効果 | V11: ＳＥ
B12: 命中力 | C12: =D5 -> 0 | P12: － | Q12: － | R12: － | S12: － | T12: － | U12: － | V12: － | W12: － | X12: －
B13: 回避力 | C13: =D5 -> 0 | S13: － | T13: － | U13: － | V13: － | W13: － | X13: －
B14: 防御力 | C14: =IF(K2="攻撃型",ROUNDDOWN(C23/3,0),0) -> 0 | P14: 効果補足
B15: 精神抵抗 | C15: =IF(K2="攻撃型",ROUNDDOWN(C23/3,0),0) -> 0
B16: 行動値 | C16: =D5 -> 0
P17: ※この行には具体的な補正量やトリガー条件などをお書き下さい。
B18: 攻撃力 | D18: ダメージボーナス | F18: 命中回避ダイス | G18: 探索判定ダイス
B19: =キャラシート!G35 -> 2 | C19: =キャラシート!H35 -> 0 | D19: =IF(K2="攻撃型",ROUNDDOWN(C23/3,0),0) -> 0 | F19: =IF(K2="速度型","2D6","1D6") -> 1D6 | G19: =IF(K2="探索型","2D6","1D6") -> 1D6 | P19: 技名 | V19: 技系統 | W19: 消費 | X19: 必要スペック
V20: －
B21: 能力名
P22: 発動系統 | S22: 付加効果 | V22: ＳＥ
B23: 能力精度 | C23: =キャラシート!H25 -> 6 | E23: 発動スペック | F23: =キャラシート!H27 -> 2 | P23: － | Q23: － | R23: － | S23: － | T23: － | U23: － | V23: － | W23: － | X23: －
B24: 能力説明 | S24: － | T24: － | U24: － | V24: － | W24: － | X24: －
P25: 効果補足
P28: ※この行には具体的な補正量やトリガー条件などをお書き下さい。
P30: 技名 | V30: 技系統 | W30: 消費 | X30: 必要スペック
B31: クリーチャー説明 | V31: －
P33: 発動系統 | S33: 付加効果 | V33: ＳＥ
P34: － | Q34: － | R34: － | S34: － | T34: － | U34: － | V34: － | W34: － | X34: －
S35: － | T35: － | U35: － | V35: － | W35: － | X35: －
P36: 効果補足
P39: ※この行には具体的な補正量やトリガー条件などをお書き下さい。
P41: 技名 | V41: 技系統 | W41: 消費 | X41: 必要スペック
V42: －
P44: 発動系統 | S44: 付加効果 | V44: ＳＥ
P45: － | Q45: － | R45: － | S45: － | T45: － | U45: － | V45: － | W45: － | X45: －
S46: － | T46: － | U46: － | V46: － | W46: － | X46: －
P47: 効果補足
P50: ※この行には具体的な補正量やトリガー条件などをお書き下さい。
P52: 技名 | V52: 技系統 | W52: 消費 | X52: 必要スペック
V53: －
P55: 発動系統 | S55: 付加効果 | V55: ＳＥ
P56: － | Q56: － | R56: － | S56: － | T56: － | U56: － | V56: － | W56: － | X56: －
...

Sheet 進行表
A1: ●補正部分は【 活性タイプ 】を選択したら、暴走率によって自動反映します。
A2: ●ＳＳ・命中・回避の入力は【 2桁以上の数字 】を入力する事で自動変換の入力補助になってます。
A3: ※「101」と入力したら「10＋1D6」と反映。下1桁がダイス数扱いとなる。
A4: ●上記同様に攻撃力の入力は【 3桁の数字 】を入力する事で自動変換の入力補助になってます。
A5: ※「101」と入力したら「1D6+１」と反映。仮に4桁の「1011」と入力したら「10D6+11」と反映される。
B7: →手入力 | C7: 共有メモ
B8: →選択入力
M9: メモ欄 | N9: →
B10: →自動反映
B11: →自動反映
B13: →ＨＰ結果
B14: →ＰＰ結果
B15: →暴走率結果
A17: キャラクター名 | E17: ＰＬ名 | G17: 活性タイプ | I17: アイテム欄 | M17: メモ欄 | N17: →
A18: =キャラシート!B3 -> 園 松温（その しょうおん） | E18: =キャラシート!J3 -> はむぱん | G18: 感覚型
A19: ＨＰ | C19: PP | E19: 暴走率 | G19: ＳＰＥ
A20: =B20+SUM(O24:IL24) -> 11 | B20: =J24+L24 -> 11 | C20: =D20-SUM(O25:IL25)+SUM(O26:IL26) -> 24 | D20: =J26+L26 -> 24 | E20: =J27+L27 -> 22 | F20: =E20+SUM(O27:IL27) -> 22 | G20: 奇跡
A21: 行動値 | B21: =キャラシート!D27 -> 6 | C21: 総消費PP | D21: 因子Ｄ | E21: =IF(F20<100,IF(F20<50,"通常状態",IF(F20<60,"暴走Lv1 ",IF(F20<70,"暴走Lv2",IF(F20<80,"暴走Lv3",IF(F20<90,"暴走Lv4","暴走Lv5"))))),IF(F20<110,"臨界Lv1",IF(F20<120,"臨界Lv2",IF(F20<130,"臨界Lv3",IF(F20<140,"臨界Lv4",IF(F20<150,"臨界Lv5",IF(F20<150,"活性Lv5","因子崩壊"))))))) -> 通常状態 | G21: カルマ
C22: =SUM(L25:IQ25) -> 0 | D22: =ROUNDDOWN((C22/5),0)+SUM(I23:IL23) -> 0 | E22: =IF(F20<50,"未活性",IF(F20<60,"活性Lv1",IF(F20<70,"活性Lv2",IF(F20<80,"活性Lv3",IF(F20<90,"活性Lv4",IF(F20<100,"活性Lv5",IF(F20<150,"活性Lv5","強制キャラロスト"))))))) -> 未活性 | G22: 芸人
A23: ＳＳ | B23: =キャラシート!C31&"+"&キャラシート!D31&"D6" -> 6+1D6 | C23: =IF(G18="反応型",IF(50>F20,"+0",IF(60>F20,"+1",IF(70>F20,"+2",IF(F20>=70,"+3")))),"活性補正") -> 活性補正 | D23: 格闘 | E23: =キャラシート!G31&"D6"&"+"&キャラシート!H31 -> 1D6+0 | F23: =IF(G18="増強型",IF(50>F20,"+0",IF(60>F20,"+1",IF(70>F20,"+2",IF(F20>=70,"+3")))),"活性補正") -> 活性補正 | G23: 因子Ｄ増減欄⇒ | I23: condition | M23: ±入力 | N23: →
A24: 命中 | B24: =キャラシート!C33&"+"&キャラシート!D33&"D6" -> 10+1D6 | D24: 武器 | E24: =キャラシート!G33&"D6"&"+"&キャラシート!H33 -> 3D6+0 | G24: ＨＰ変動欄⇒ | I24: 素HP | J24: =キャラシート!D17 -> 8 | K24: 追加HP | L24: 3 | M24: ±入力 | N24: →
A25: 回避 | B25: =キャラシート!C35&"+"&キャラシート!D35&"D6" -> 11+1D6 | D25: 能力 | E25: =キャラシート!G35&"D6"&"+"&キャラシート!H35 -> 2D6+0 | G25: 消費ＰＰ欄⇒ | M25: プラス入力のみ | N25: →
A26: 防御 | B26: =キャラシート!D23 -> 2 | C26: =IF(G18="増強型",IF(50>F20,"+0",IF(60>F20,"+1",IF(70>F20,"+2",IF(F20>=70,"+3")))),"活性補正") -> 活性補正 | D26: 精度 | E26: =キャラシート!H25 -> 6 | G26: 回復ＰＰ欄⇒ | I26: 素PP | J26: =キャラシート!D19 -> 17 | K26: 追加PP | L26: 7 | M26: プラス入力のみ | N26: →
A27: 抵抗 | B27: =キャラシート!D25 -> 2 | D27: スペック | E27: =キャラシート!H27 -> 2 | F27: =IF(G18="覚醒型",IF(50>F20,"+0",IF(60>F20,"+1",IF(70>F20,"+2",IF(F20>=70,"+3")))),"活性補正") -> 活性補正 | G27: 暴走率変動欄⇒ | I27: 素暴走 | J27: =キャラシート!D21 -> 15 | K27: 追加暴走 | L27: =L26 -> 7 | M27: ±入力 | N27: →
A28: 力技 | B28: =キャラシート!P15+キャラシート!Q15 -> 1 | C28: 観察眼 | D28: =キャラシート!P17+キャラシート!Q17 -> 3 | E28: 知識 | F28: =キャラシート!P19+キャラシート!Q19 -> 5 | G28: 隠密 | H28: =キャラシート!P21+キャラシート!Q21 -> 7 | I28: 話術 | J28: =キャラシート!P23+キャラシート!Q23 -> 6 | K28: 閃き | L28: =キャラシート!P25+キャラシート!Q25 -> 1
A29: 威圧 | B29: =キャラシート!P16+キャラシート!Q16 -> 2 | C29: 察知 | D29: =キャラシート!P18+キャラシート!Q18 -> 4 | E29: 技術 | F29: =キャラシート!P20+キャラシート!Q20 -> 5 | G29: 俊敏 | H29: =キャラシート!P22+キャラシート!Q22 -> 7 | I29: 読心 | J29: =キャラシート!P24+キャラシート!Q24 -> 2 | K29: 幸運 | L29: =キャラシート!P26+キャラシート!Q26 -> 1
A31: キャラクター名 | E31: ＰＬ名 | G31: 活性タイプ | I31: アイテム欄 | M31: メモ欄 | N31: →
G32: －
A33: ＨＰ | C33: PP | E33: 暴走率 | G33: ＳＰＥ
A34: =B34+SUM(O38:IL38) -> 0 | B34: =J38+L38 -> 0 | C34: =D34-SUM(O39:IL39)+SUM(O40:IL40) -> 0 | D34: =J40+L40 -> 0 | E34: =J41+L41 -> 0 | F34: =E34+SUM(O41:IL41) -> 0 | G34: －
A35: 行動値 | C35: 総消費PP | D35: 因子Ｄ | E35: =IF(F34<100,IF(F34<50,"通常状態",IF(F34<60,"暴走Lv1 ",IF(F34<70,"暴走Lv2",IF(F34<80,"暴走Lv3",IF(F34<90,"暴走Lv4","暴走Lv5"))))),IF(F34<110,"臨界Lv1",IF(F34<120,"臨界Lv2",IF(F34<130,"臨界Lv3",IF(F34<140,"臨界Lv4",IF(F34<150,"臨界Lv5",IF(F34<150,"活性Lv5","因子崩壊"))))))) -> 通常状態 | G35: カルマ
C36: =SUM(L39:IQ39) -> 0 | D36: =ROUNDDOWN((C36/5),0)+SUM(I37:IL37) -> 0 | E36: =IF(F34<50,"未活性",IF(F34<60,"活性Lv1",IF(F34<70,"活性Lv2",IF(F34<80,"活性Lv3",IF(F34<90,"活性Lv4",IF(F34<100,"活性Lv5",IF(F34<150,"活性Lv5","強制キャラロスト"))))))) -> 未活性 | G36: －
A37: ＳＳ | C37: =IF(G32="反応型",IF(50>F34,"+0",IF(60>F34,"+1",IF(70>F34,"+2",IF(F34>=70,"+3")))),"活性補正") -> 活性補正 | D37: 格闘 | F37: =IF(G32="増強型",IF(50>F34,"+0",IF(60>F34,"+1",IF(70>F34,"+2",IF(F34>=70,"+3")))),"活性補正") -> 活性補正 | G37: 因子Ｄ増減欄⇒ | I37: condition | M37: ±入力 | N37: →
A38: 命中 | D38: 武器 | G38: ＨＰ変動欄⇒ | I38: 素HP | K38: 追加HP | M38: ±入力 | N38: →
A39: 回避 | D39: 能力 | G39: 消費ＰＰ欄⇒ | M39: プラス入力のみ | N39: →
A40: 防御 | C40: =IF(G32="増強型",IF(50>F34,"+0",IF(60>F34,"+1",IF(70>F34,"+2",IF(F34>=70,"+3")))),"活性補正") -> 活性補正 | D40: 精度 | G40: 回復ＰＰ欄⇒ | I40: 素PP | K40: 追加PP | M40: プラス入力のみ | N40: →
A41: 抵抗 | D41: スペック | F41: =IF(G32="覚醒型",IF(50>F34,"+0",IF(60>F34,"+1",IF(70>F34,"+2",IF(F34>=70,"+3")))),"活性補正") -> 活性補正 | G41: 暴走率変動欄⇒ | I41: 素暴走 | K41: 追加暴走 | L41: =L40 -> 0 | M41: ±入力 | N41: →
A42: 力技 | C42: 観察眼 | E42: 知識 | G42: 隠密 | I42: 話術 | K42: 閃き
A43: 威圧 | C43: 察知 | E43: 技術 | G43: 俊敏 | I43: 読心 | K43: 幸運
A45: キャラクター名 | E45: ＰＬ名 | G45: 活性タイプ | I45: アイテム欄 | M45: メモ欄 | N45: →
...
